Em .NET e C#, o `throw` é utilizado para lançar exceções. Quando você encontra uma condição que o código não pode tratar, como um valor inválido ou um erro que você deseja capturar mais tarde, você pode usar `throw` para interromper o fluxo normal do programa e "lançar" uma exceção. Isso permite que o erro seja tratado em um nível superior do código, onde há uma cláusula `try-catch` que pode lidar com a exceção.

### Sintaxe básica

Aqui está a sintaxe básica para lançar uma exceção:

```csharp
throw new Exception("Mensagem de erro");
```

### Exemplo básico

Vamos ver um exemplo de uso do `throw`:

```csharp
public class Calculadora
{
    public int Dividir(int numerador, int denominador)
    {
        if (denominador == 0)
        {
            throw new DivideByZeroException("Denominador não pode ser zero.");
        }
        
        return numerador / denominador;
    }
}
```

Neste exemplo, se o denominador for zero, o método `Dividir` lança uma exceção `DivideByZeroException`, que é uma exceção específica para operações de divisão por zero.

### Relançando uma exceção

Às vezes, você pode capturar uma exceção e depois decidir relançá-la para que seja tratada em outro lugar. Isso pode ser feito com o `throw` sem parâmetros, como mostrado abaixo:

```csharp
try
{
    // Código que pode lançar uma exceção
}
catch (Exception ex)
{
    // Tratamento de exceção
    Console.WriteLine("Erro: " + ex.Message);
    throw; // Relança a exceção para ser tratada em outro lugar
}
```

### Exemplo prático

```csharp
public class Exemplo
{
    public void Processar(int valor)
    {
        try
        {
            if (valor < 0)
            {
                throw new ArgumentOutOfRangeException(nameof(valor), "O valor não pode ser negativo.");
            }

            Console.WriteLine("Processando valor: " + valor);
        }
        catch (ArgumentOutOfRangeException ex)
        {
            Console.WriteLine("Erro: " + ex.Message);
            throw; // Relança a exceção
        }
    }
}
```

Neste exemplo, o método `Processar` verifica se o valor é negativo e, se for, lança uma exceção `ArgumentOutOfRangeException`. Se essa exceção for capturada, ela é relançada para ser tratada em outro lugar, como no nível superior da aplicação.

### Considerações finais

- O `throw` interrompe o fluxo do programa e inicia a busca por um bloco `catch` que possa tratar a exceção.
- Usar exceções de forma adequada é importante para criar código robusto e fácil de manter.
- Relançar exceções pode ser útil quando você quer adicionar informações de depuração ou log antes de permitir que a exceção seja tratada em outro lugar.

Se precisar de um exemplo mais específico ou tiver outra dúvida, posso ajudar!